Workbook

Sheet Cover
B2: TICKER-TO-THESIS · EQUITY RESEARCH MODEL
B4: NIKE, Inc. (NKE)
B5: Rubber & Plastics Footwear · fiscal year ends 05/31 · model date 2026-10-12 · Abhishek Raut
B7: Rating | C7: =Valuation!$C$20
B8: Price target ($) | C8: =Valuation!$C$17
B9: Current price ($) | C9: =Assumptions!$C$17
B10: Upside / (downside) | C10: =Valuation!$C$19
B11: Market cap ($m) | C11: =Assumptions!$C$23
B12: Enterprise value ($m) | C12: =Assumptions!$C$23+Assumptions!$C$22
B13: WACC | C13: =WACC!$C$25
B14: DCF value per share, perpetuity ($) | C14: =DCF!$C$32
B15: DCF value per share, exit multiple ($) | C15: =DCF!$C$42
B18: How to use this model
B19: 1. Assumptions: change blue/yellow cells (growth, margins, ERP, terminal growth, exit multiple) or switch the scenario.
B20: 2. DCF and Sensitivity recalculate live; Valuation shows the football field, blended price target and rating.
B21: 3. Comps: peer multiples and implied values. Benchmark: target vs peer distribution and trends.
B22: 4. Sources: the XBRL tag and SEC filing behind every historical number.
B23: 5. Colour code: blue = input, black = formula, green = link to another sheet, yellow fill = key assumption.
B27: Educational project generated from public SEC filings and market data. Not investment advice.

Sheet Assumptions
B1: NIKE, Inc. (NKE): assumptions
B2: Blue = input. Yellow = key assumption. Edit these cells; everything else recalculates.
B3: Scenario
B4: Active scenario (1 = Base, 2 = Bear, 3 = Bull) | C4: 1
B6: Market & valuation inputs
B7: Risk-free rate (10-year Treasury) | C7: 0.0522 | H7: FRED DGS10 (10-year Treasury), 2026-10-08
B8: Equity risk premium | C8: 0.045 | H8: Config assumption; update from Damodaran's latest implied ERP.
B9: Marginal tax rate (debt shield, beta unlevering) | C9: 0.25 | H9: US federal 21% + typical state.
B10: Credit spread (synthetic rating AAA) | C10: 0.006 | H10: Interest coverage 11.8x maps to AAA; spread after Damodaran's table (approximate).
B11: Terminal growth rate | C11: 0.025 | H11: Long-run nominal growth assumption (config).
B12: Exit multiple (EV / EBITDA) | C12: 8.5652069 | H12: Peer median EV / EBITDA (latest fiscal year).
B13: Minimum WACC spread over terminal growth | C13: 0.02 | H13: Sanity floor.
B14: Mid-year discounting (1 = on, 0 = off) | C14: 1 | H14: Cash flows arrive mid-year on average.
B16: Market data (latest balance sheet 2026-08-31; $m except per share)
B17: Share price ($) | C17: 35.055 | H17: Latest close, 2026-10-12.
B18: Shares outstanding (m) | C18: 1484.2 | H18: WeightedAverageNumberOfDilutedSharesOutstanding (latest period), 2026-08-31.
B19: Cash & equivalents | C19: 6903 | H19: Latest 10-Q/10-K.
B20: Short-term investments | C20: 1465 | H20: Latest 10-Q/10-K.
B21: Total debt (excl. operating leases) | C21: 7893 | H21: Long-term debt incl. current portion + short-term borrowings.
B22: Net debt | C22: =Assumptions!$C$21-Assumptions!$C$19-Assumptions!$C$20
B23: Market capitalisation | C23: =Assumptions!$C$17*Assumptions!$C$18
B25: Operating drivers (base case)
B26: Driver | C26: Year 1 | D26: Year 2 | E26: Year 3 | F26: Year 4 | G26: Year 5
B27: Revenue growth | C27: -0.08 | D27: 0.02 | E27: 0.04 | F27: 0.05 | G27: 0.04 | H27: FY27 = guidance (revenue down high-single digits, Q1 FY27 release); modest recovery thereafter as China stabilises.
B28: EBIT margin | C28: 0.05 | D28: 0.07 | E28: 0.09 | F28: 0.105 | G28: 0.115 | H28: FY27 ~5% implied by adj. EPS guidance of $1.15-1.35; rebuilds to 11.5% by FY31 as ~$2.5bn Pace savings land (below FY21-24 avg of ~13.5%).
B29: Tax rate on EBIT | C29: 0.24 | H29: Management guides a mid-20s effective tax rate for FY27.
B30: D&A % revenue | C30: 0.016111026 | H30: 3-year average D&A / revenue.
B31: Capex % revenue | C31: 0.01327894 | H31: 3-year average capex / revenue.
B32: Working capital % revenue | C32: 0.19247787 | H32: 3-year average operating working capital (receivables + inventory − payables) / revenue.
B34: Scenario shifts (added to base case)
B35: Shift | C35: Base | D35: Bear | E35: Bull
B36: Revenue growth (each year) | C36: 0 | D36: -0.03 | E36: 0.03
B37: EBIT margin (each year) | C37: 0 | D37: -0.02 | E37: 0.02
B38: WACC | C38: 0 | D38: 0.01 | E38: -0.01
B39: Terminal growth | C39: 0 | D39: -0.005 | E39: 0.005
B41: Price target weights & rating thresholds
B42: Weight: DCF (perpetuity growth) | C42: 0.5
B43: Weight: DCF (exit multiple) | C43: 0.25
B44: Weight: trading comps (EV/EBITDA median) | C44: 0.25
B45: BUY if upside above | C45: 0.15
...

Sheet Historicals
B1: NIKE, Inc.: standardised historical financials ($m)
B2: Source: SEC EDGAR XBRL (10-K). See Sources sheet for the tag and filing behind every value.
B4: Fiscal year | C4: FY2019 | D4: FY2020 | E4: FY2021 | F4: FY2022 | G4: FY2023 | H4: FY2024 | I4: FY2025 | J4: FY2026
B5: Revenue | C5: 39117 | D5: 37403 | E5: 44538 | F5: 46710 | G5: 51217 | H5: 51362 | I5: 46309 | J5: 46398
B6: Cost of revenue | C6: 21643 | D6: 21162 | E6: 24576 | F6: 25231 | G6: 28925 | H6: 28475 | I6: 26519 | J6: 26487
B7: Gross profit | C7: 17474 | D7: 16241 | E7: 19962 | F7: 21479 | G7: 22292 | H7: 22887 | I7: 19790 | J7: 19911
B8: Operating income (EBIT) | C8: 4772 | D8: 3115 | E8: 6937 | F8: 6675 | G8: 5915 | H8: 6311 | I8: 3702 | J8: 3797
B9: Depreciation & amortisation | C9: 705 | D9: 721 | E9: 744 | F9: 717 | G9: 703 | H9: 796 | I9: 775 | J9: 747
B10: EBITDA | C10: =C8+C9 | D10: =D8+D9 | E10: =E8+E9 | F10: =F8+F9 | G10: =G8+G9 | H10: =H8+H9 | I10: =I8+I9 | J10: =J8+J9
B11: Interest expense | C11: 153 | D11: 140 | E11: 293 | F11: 290 | G11: 347 | H11: 381 | I11: 389 | J11: 323
B12: Pre-tax income | C12: 4801 | D12: 2887 | E12: 6661 | F12: 6651 | G12: 6201 | H12: 6700 | I12: 3885 | J12: 3900
B13: Income tax | C13: 772 | D13: 348 | E13: 934 | F13: 605 | G13: 1131 | H13: 1000 | I13: 666 | J13: 792
B14: Net income | C14: 4029 | D14: 2539 | E14: 5727 | F14: 6046 | G14: 5070 | H14: 5700 | I14: 3219 | J14: 3108
B15: Cash from operations | C15: 5903 | D15: 2485 | E15: 6657 | F15: 5188 | G15: 5841 | H15: 7429 | I15: 3698 | J15: 2868
B16: Capital expenditure | C16: 1119 | D16: 1086 | E16: 695 | F16: 758 | G16: 969 | H16: 812 | I16: 430 | J16: 684
B17: Free cash flow | C17: =C15-C16 | D17: =D15-D16 | E17: =E15-E16 | F17: =F15-F16 | G17: =G15-G16 | H17: =H15-H16 | I17: =I15-I16 | J17: =J15-J16
B18: Stock-based compensation | C18: 325 | D18: 429 | E18: 611 | F18: 638 | G18: 755 | H18: 804 | I18: 709 | J18: 715
B19: Dividends paid | C19: 1332 | D19: 1452 | E19: 1638 | F19: 1837 | G19: 2012 | H19: 2169 | I19: 2300 | J19: 2407
B20: Share repurchases | C20: 4286 | D20: 3067 | E20: 608 | F20: 4014 | G20: 5480 | H20: 4250 | I20: 2985 | J20: 146
B21: Cash & equivalents | C21: 4466 | D21: 8348 | E21: 9889 | F21: 8574 | G21: 7441 | H21: 9860 | I21: 7464 | J21: 7563
B22: Short-term investments | C22: 197 | D22: 439 | E22: 3587 | F22: 4423 | G22: 3234 | H22: 1722 | I22: 1687 | J22: 1464
B23: Accounts receivable | C23: 4272 | D23: 2749 | E23: 4463 | F23: 4667 | G23: 4131 | H23: 4427 | I23: 4717 | J23: 5931
B24: Inventory | C24: 5622 | D24: 7367 | E24: 6854 | F24: 8420 | G24: 8454 | H24: 7519 | I24: 7489 | J24: 7501
B25: Accounts payable | C25: 2612 | D25: 2248 | E25: 2836 | F25: 3358 | G25: 2862 | H25: 2851 | I25: 3479 | J25: 3600
B26: Total assets | C26: 23717 | D26: 31342 | E26: 37740 | F26: 40321 | G26: 37531 | H26: 38110 | I26: 36579 | J26: 38410
B27: Shareholders' equity | C27: 9040 | D27: 8055 | E27: 12767 | F27: 15281 | G27: 14004 | H27: 14430 | I27: 13213 | J27: 14865
B28: Total debt | C28: 3479 | D28: 9657 | E28: 9415 | F28: 9430 | G28: 8933 | H28: 8909 | I28: 7966 | J28: 7942
B29: Net debt | C29: =C28-C21-C22 | D29: =D28-D21-D22 | E29: =E28-E21-E22 | F29: =F28-F21-F22 | G29: =G28-G21-G22 | H29: =H28-H21-H22 | I29: =I28-I21-I22 | J29: =J28-J21-J22
B30: Operating working capital | C30: =C23+C24-C25 | D30: =D23+D24-D25 | E30: =E23+E24-E25 | F30: =F23+F24-F25 | G30: =G23+G24-G25 | H30: =H23+H24-H25 | I30: =I23+I24-I25 | J30: =J23+J24-J25
B32: Ratios (formulas)
B33: Revenue growth | D33: =IFERROR(D5/C5-1,"") | E33: =IFERROR(E5/D5-1,"") | F33: =IFERROR(F5/E5-1,"") | G33: =IFERROR(G5/F5-1,"") | H33: =IFERROR(H5/G5-1,"") | I33: =IFERROR(I5/H5-1,"") | J33: =IFERROR(J5/I5-1,"")
B34: Gross margin | C34: =IFERROR(C7/C5,"") | D34: =IFERROR(D7/D5,"") | E34: =IFERROR(E7/E5,"") | F34: =IFERROR(F7/F5,"") | G34: =IFERROR(G7/G5,"") | H34: =IFERROR(H7/H5,"") | I34: =IFERROR(I7/I5,"") | J34: =IFERROR(J7/J5,"")
B35: EBIT margin | C35: =IFERROR(C8/C5,"") | D35: =IFERROR(D8/D5,"") | E35: =IFERROR(E8/E5,"") | F35: =IFERROR(F8/F5,"") | G35: =IFERROR(G8/G5,"") | H35: =IFERROR(H8/H5,"") | I35: =IFERROR(I8/I5,"") | J35: =IFERROR(J8/J5,"")
B36: EBITDA margin | C36: =IFERROR(C10/C5,"") | D36: =IFERROR(D10/D5,"") | E36: =IFERROR(E10/E5,"") | F36: =IFERROR(F10/F5,"") | G36: =IFERROR(G10/G5,"") | H36: =IFERROR(H10/H5,"") | I36: =IFERROR(I10/I5,"") | J36: =IFERROR(J10/J5,"")
B37: Net margin | C37: =IFERROR(C14/C5,"") | D37: =IFERROR(D14/D5,"") | E37: =IFERROR(E14/E5,"") | F37: =IFERROR(F14/F5,"") | G37: =IFERROR(G14/G5,"") | H37: =IFERROR(H14/H5,"") | I37: =IFERROR(I14/I5,"") | J37: =IFERROR(J14/J5,"")
B38: FCF margin | C38: =IFERROR(C17/C5,"") | D38: =IFERROR(D17/D5,"") | E38: =IFERROR(E17/E5,"") | F38: =IFERROR(F17/F5,"") | G38: =IFERROR(G17/G5,"") | H38: =IFERROR(H17/H5,"") | I38: =IFERROR(I17/I5,"") | J38: =IFERROR(J17/J5,"")
B39: Effective tax rate | C39: =IFERROR(C13/C12,"") | D39: =IFERROR(D13/D12,"") | E39: =IFERROR(E13/E12,"") | F39: =IFERROR(F13/F12,"") | G39: =IFERROR(G13/G12,"") | H39: =IFERROR(H13/H12,"") | I39: =IFERROR(I13/I12,"") | J39: =IFERROR(J13/J12,"")
B40: D&A % revenue | C40: =IFERROR(C9/C5,"") | D40: =IFERROR(D9/D5,"") | E40: =IFERROR(E9/E5,"") | F40: =IFERROR(F9/F5,"") | G40: =IFERROR(G9/G5,"") | H40: =IFERROR(H9/H5,"") | I40: =IFERROR(I9/I5,"") | J40: =IFERROR(J9/J5,"")
B41: Capex % revenue | C41: =IFERROR(C16/C5,"") | D41: =IFERROR(D16/D5,"") | E41: =IFERROR(E16/E5,"") | F41: =IFERROR(F16/F5,"") | G41: =IFERROR(G16/G5,"") | H41: =IFERROR(H16/H5,"") | I41: =IFERROR(I16/I5,"") | J41: =IFERROR(J16/J5,"")
B42: Working capital % revenue | C42: =IFERROR(C30/C5,"") | D42: =IFERROR(D30/D5,"") | E42: =IFERROR(E30/E5,"") | F42: =IFERROR(F30/F5,"") | G42: =IFERROR(G30/G5,"") | H42: =IFERROR(H30/H5,"") | I42: =IFERROR(I30/I5,"") | J42: =IFERROR(J30/J5,"")
...

Sheet WACC
B1: NKE: cost of capital
B2: Bottom-up beta: peers' regression betas, unlevered, median, relevered at the target's capital structure.
B4: Company | C4: Raw beta (2y weekly) | D4: R² | E4: Adjusted beta | F4: Market cap ($m) | G4: Debt ($m) | H4: Debt / equity | I4: Unlevered beta | J4: Role
B5: NKE | C5: 1.0001011 | D5: 0.17353135 | E5: =IF(C5="","",0.67*C5+0.33) | F5: 52028.631 | G5: 7893 | H5: =IFERROR(G5/F5,0) | I5: =IF(E5="","",E5/(1+(1-Assumptions!$C$9)*H5)) | J5: Target
B6: LULU | C6: 1.0953729 | D6: 0.12238656 | E6: =IF(C6="","",0.67*C6+0.33) | F6: 9955.9367 | G6: 0 | H6: =IFERROR(G6/F6,0) | I6: =IF(E6="","",E6/(1+(1-Assumptions!$C$9)*H6)) | J6: Peer
B7: DECK | C7: 1.3460278 | D7: 0.19880679 | E7: =IF(C7="","",0.67*C7+0.33) | F7: 11395.703 | G7: 0 | H7: =IFERROR(G7/F7,0) | I7: =IF(E7="","",E7/(1+(1-Assumptions!$C$9)*H7)) | J7: Peer
B8: CROX | C8: 0.77661221 | D8: 0.058086739 | E8: =IF(C8="","",0.67*C8+0.33) | F8: 5651.7653 | G8: 1334 | H8: =IFERROR(G8/F8,0) | I8: =IF(E8="","",E8/(1+(1-Assumptions!$C$9)*H8)) | J8: Peer
B9: UAA | C9: 0.99706518 | D9: 0.088570078 | E9: =IF(C9="","",0.67*C9+0.33) | F9: 2133.7688 | G9: 591.158 | H9: =IFERROR(G9/F9,0) | I9: =IF(E9="","",E9/(1+(1-Assumptions!$C$9)*H9)) | J9: Peer
B10: VFC | C10: 1.8539076 | D10: 0.23994 | E10: =IF(C10="","",0.67*C10+0.33) | F10: 6176.2495 | G10: 3530.009 | H10: =IFERROR(G10/F10,0) | I10: =IF(E10="","",E10/(1+(1-Assumptions!$C$9)*H10)) | J10: Peer
B11: COLM | C11: 0.62989504 | D11: 0.076208238 | E11: =IF(C11="","",0.67*C11+0.33) | F11: 2884.7364 | G11: 0 | H11: =IFERROR(G11/F11,0) | I11: =IF(E11="","",E11/(1+(1-Assumptions!$C$9)*H11)) | J11: Peer
B13: Median unlevered beta (peers) | C13: =MEDIAN(I6:I11)
B14: Target debt / equity (market) | C14: =Assumptions!$C$21/Assumptions!$C$23
B15: Relevered beta | C15: =C13*(1+(1-Assumptions!$C$9)*C14) | D15: Target's own adjusted beta: 1.00 (shown for reference)
B16: Risk-free rate | C16: =Assumptions!$C$7
B17: Equity risk premium | C17: =Assumptions!$C$8
B18: Cost of equity | C18: =C16+C15*C17
B19: Pre-tax cost of debt (rf + spread) | C19: =Assumptions!$C$7+Assumptions!$C$10
B20: After-tax cost of debt | C20: =C19*(1-Assumptions!$C$9)
B21: Weight of equity | C21: =Assumptions!$C$23/(Assumptions!$C$23+Assumptions!$C$21)
B22: Weight of debt | C22: =1-C21
B23: WACC (calculated) | C23: =C21*C18+C22*C20
B24: WACC (after floor: terminal growth + min spread) | C24: =MAX(C23,Assumptions!$C$11+Assumptions!$C$13)
B25: WACC used (incl. scenario shift) | C25: =C24+INDEX(Assumptions!$C$38:$E$38,Assumptions!$C$4)

Sheet DCF
B1: NKE: discounted cash flow ($m)
B2: Unlevered free cash flow = EBIT × (1 − tax) + D&A − capex − Δ working capital. Mid-year discounting.
C4: FY2026A | D4: Year 1 | E4: Year 2 | F4: Year 3 | G4: Year 4 | H4: Year 5
B5: Year number | D5: 1 | E5: 2 | F5: 3 | G5: 4 | H5: 5
B6: Revenue | C6: =Historicals!$J$5 | D6: =C6*(1+D7) | E6: =D6*(1+E7) | F6: =E6*(1+F7) | G6: =F6*(1+G7) | H6: =G6*(1+H7)
B7: Revenue growth | D7: =Assumptions!C27+INDEX(Assumptions!$C$36:$E$36,Assumptions!$C$4) | E7: =Assumptions!D27+INDEX(Assumptions!$C$36:$E$36,Assumptions!$C$4) | F7: =Assumptions!E27+INDEX(Assumptions!$C$36:$E$36,Assumptions!$C$4) | G7: =Assumptions!F27+INDEX(Assumptions!$C$36:$E$36,Assumptions!$C$4) | H7: =Assumptions!G27+INDEX(Assumptions!$C$36:$E$36,Assumptions!$C$4)
B8: EBIT margin | D8: =Assumptions!C28+INDEX(Assumptions!$C$37:$E$37,Assumptions!$C$4) | E8: =Assumptions!D28+INDEX(Assumptions!$C$37:$E$37,Assumptions!$C$4) | F8: =Assumptions!E28+INDEX(Assumptions!$C$37:$E$37,Assumptions!$C$4) | G8: =Assumptions!F28+INDEX(Assumptions!$C$37:$E$37,Assumptions!$C$4) | H8: =Assumptions!G28+INDEX(Assumptions!$C$37:$E$37,Assumptions!$C$4)
B9: EBIT | D9: =D6*D8 | E9: =E6*E8 | F9: =F6*F8 | G9: =G6*G8 | H9: =H6*H8
B10: Taxes on EBIT | D10: =D9*Assumptions!$C$29 | E10: =E9*Assumptions!$C$29 | F10: =F9*Assumptions!$C$29 | G10: =G9*Assumptions!$C$29 | H10: =H9*Assumptions!$C$29
B11: NOPAT | D11: =D9-D10 | E11: =E9-E10 | F11: =F9-F10 | G11: =G9-G10 | H11: =H9-H10
B12: D&A | D12: =D6*Assumptions!$C$30 | E12: =E6*Assumptions!$C$30 | F12: =F6*Assumptions!$C$30 | G12: =G6*Assumptions!$C$30 | H12: =H6*Assumptions!$C$30
B13: Capex | D13: =D6*Assumptions!$C$31 | E13: =E6*Assumptions!$C$31 | F13: =F6*Assumptions!$C$31 | G13: =G6*Assumptions!$C$31 | H13: =H6*Assumptions!$C$31
B14: Working capital | C14: =C6*Assumptions!$C$32 | D14: =D6*Assumptions!$C$32 | E14: =E6*Assumptions!$C$32 | F14: =F6*Assumptions!$C$32 | G14: =G6*Assumptions!$C$32 | H14: =H6*Assumptions!$C$32
B15: Δ Working capital | D15: =D14-C14 | E15: =E14-D14 | F15: =F14-E14 | G15: =G14-F14 | H15: =H14-G14
B16: Unlevered free cash flow | D16: =D11+D12-D13-D15 | E16: =E11+E12-E13-E15 | F16: =F11+F12-F13-F15 | G16: =G11+G12-G13-G15 | H16: =H11+H12-H13-H15
B17: EBITDA | D17: =D9+D12 | E17: =E9+E12 | F17: =F9+F12 | G17: =G9+G12 | H17: =H9+H12
B18: Discount period (years) | D18: =D5-0.5*Assumptions!$C$14 | E18: =E5-0.5*Assumptions!$C$14 | F18: =F5-0.5*Assumptions!$C$14 | G18: =G5-0.5*Assumptions!$C$14 | H18: =H5-0.5*Assumptions!$C$14
B19: Discount factor | D19: =1/(1+$C$23)^D18 | E19: =1/(1+$C$23)^E18 | F19: =1/(1+$C$23)^F18 | G19: =1/(1+$C$23)^G18 | H19: =1/(1+$C$23)^H18
B20: PV of UFCF | D20: =D16*D19 | E20: =E16*E19 | F20: =F16*F19 | G20: =G16*G19 | H20: =H16*H19
B22: Perpetuity growth method
B23: WACC | C23: =WACC!$C$25
B24: Terminal growth | C24: =Assumptions!$C$11+INDEX(Assumptions!$C$39:$E$39,Assumptions!$C$4)
B25: Sum of PV of UFCF | C25: =SUM(D20:H20)
B26: Terminal value | C26: =H16*(1+C24)/(C23-C24) | I26: Gordon growth: UFCF in year N × (1 + g) / (WACC − g), discounted from the end of year N.
B27: PV of terminal value | C27: =C26/(1+C23)^H5
B28: Enterprise value | C28: =C25+C27
B29: Less: net debt | C29: =Assumptions!$C$22
B30: Equity value | C30: =C28-C29
B31: Shares outstanding (m) | C31: =Assumptions!$C$18
B32: Value per share ($) | C32: =C30/C31
B33: Terminal value % of EV | C33: =C27/C28
B34: Implied exit multiple (EV/EBITDA) | C34: =C26/H17
B36: Exit multiple method
B37: Exit multiple (EV/EBITDA) | C37: =Assumptions!$C$12
B38: Terminal value | C38: =H17*C37
B39: PV of terminal value | C39: =C38/(1+C23)^H5
B40: Enterprise value | C40: =C25+C39
B41: Equity value | C41: =C40-C29
B42: Value per share ($) | C42: =C41/C31
B43: Implied perpetual growth | C43: =(C38*C23-H16)/(C38+H16)

Sheet Sensitivity
B1: NKE: value per share sensitivity ($)
B2: Live formulas: each cell re-runs the DCF for that WACC and terminal assumption.
B4: WACC step | C4: 0.005 | D4: g step | E4: 0.0025 | F4: Multiple step | G4: 1
B6: Perpetuity growth method: WACC (rows) × terminal growth (columns)
B7: WACC \ g | C7: =DCF!$C$24+(-2)*$E$4 | D7: =DCF!$C$24+(-1)*$E$4 | E7: =DCF!$C$24+(0)*$E$4 | F7: =DCF!$C$24+(1)*$E$4 | G7: =DCF!$C$24+(2)*$E$4
B8: =DCF!$C$23+(-2)*$C$4 | C8: =IF($B8>C$7,(SUMPRODUCT(DCF!$D$16:$H$16/(1+$B8)^DCF!$D$18:$H$18)+DCF!$H$16*(1+C$7)/($B8-C$7)/(1+$B8)^DCF!$H$5-DCF!$C$29)/DCF!$C$31,"n/a") | D8: =IF($B8>D$7,(SUMPRODUCT(DCF!$D$16:$H$16/(1+$B8)^DCF!$D$18:$H$18)+DCF!$H$16*(1+D$7)/($B8-D$7)/(1+$B8)^DCF!$H$5-DCF!$C$29)/DCF!$C$31,"n/a") | E8: =IF($B8>E$7,(SUMPRODUCT(DCF!$D$16:$H$16/(1+$B8)^DCF!$D$18:$H$18)+DCF!$H$16*(1+E$7)/($B8-E$7)/(1+$B8)^DCF!$H$5-DCF!$C$29)/DCF!$C$31,"n/a") | F8: =IF($B8>F$7,(SUMPRODUCT(DCF!$D$16:$H$16/(1+$B8)^DCF!$D$18:$H$18)+DCF!$H$16*(1+F$7)/($B8-F$7)/(1+$B8)^DCF!$H$5-DCF!$C$29)/DCF!$C$31,"n/a") | G8: =IF($B8>G$7,(SUMPRODUCT(DCF!$D$16:$H$16/(1+$B8)^DCF!$D$18:$H$18)+DCF!$H$16*(1+G$7)/($B8-G$7)/(1+$B8)^DCF!$H$5-DCF!$C$29)/DCF!$C$31,"n/a")
B9: =DCF!$C$23+(-1)*$C$4 | C9: =IF($B9>C$7,(SUMPRODUCT(DCF!$D$16:$H$16/(1+$B9)^DCF!$D$18:$H$18)+DCF!$H$16*(1+C$7)/($B9-C$7)/(1+$B9)^DCF!$H$5-DCF!$C$29)/DCF!$C$31,"n/a") | D9: =IF($B9>D$7,(SUMPRODUCT(DCF!$D$16:$H$16/(1+$B9)^DCF!$D$18:$H$18)+DCF!$H$16*(1+D$7)/($B9-D$7)/(1+$B9)^DCF!$H$5-DCF!$C$29)/DCF!$C$31,"n/a") | E9: =IF($B9>E$7,(SUMPRODUCT(DCF!$D$16:$H$16/(1+$B9)^DCF!$D$18:$H$18)+DCF!$H$16*(1+E$7)/($B9-E$7)/(1+$B9)^DCF!$H$5-DCF!$C$29)/DCF!$C$31,"n/a") | F9: =IF($B9>F$7,(SUMPRODUCT(DCF!$D$16:$H$16/(1+$B9)^DCF!$D$18:$H$18)+DCF!$H$16*(1+F$7)/($B9-F$7)/(1+$B9)^DCF!$H$5-DCF!$C$29)/DCF!$C$31,"n/a") | G9: =IF($B9>G$7,(SUMPRODUCT(DCF!$D$16:$H$16/(1+$B9)^DCF!$D$18:$H$18)+DCF!$H$16*(1+G$7)/($B9-G$7)/(1+$B9)^DCF!$H$5-DCF!$C$29)/DCF!$C$31,"n/a")
B10: =DCF!$C$23+(0)*$C$4 | C10: =IF($B10>C$7,(SUMPRODUCT(DCF!$D$16:$H$16/(1+$B10)^DCF!$D$18:$H$18)+DCF!$H$16*(1+C$7)/($B10-C$7)/(1+$B10)^DCF!$H$5-DCF!$C$29)/DCF!$C$31,"n/a") | D10: =IF($B10>D$7,(SUMPRODUCT(DCF!$D$16:$H$16/(1+$B10)^DCF!$D$18:$H$18)+DCF!$H$16*(1+D$7)/($B10-D$7)/(1+$B10)^DCF!$H$5-DCF!$C$29)/DCF!$C$31,"n/a") | E10: =IF($B10>E$7,(SUMPRODUCT(DCF!$D$16:$H$16/(1+$B10)^DCF!$D$18:$H$18)+DCF!$H$16*(1+E$7)/($B10-E$7)/(1+$B10)^DCF!$H$5-DCF!$C$29)/DCF!$C$31,"n/a") | F10: =IF($B10>F$7,(SUMPRODUCT(DCF!$D$16:$H$16/(1+$B10)^DCF!$D$18:$H$18)+DCF!$H$16*(1+F$7)/($B10-F$7)/(1+$B10)^DCF!$H$5-DCF!$C$29)/DCF!$C$31,"n/a") | G10: =IF($B10>G$7,(SUMPRODUCT(DCF!$D$16:$H$16/(1+$B10)^DCF!$D$18:$H$18)+DCF!$H$16*(1+G$7)/($B10-G$7)/(1+$B10)^DCF!$H$5-DCF!$C$29)/DCF!$C$31,"n/a")
B11: =DCF!$C$23+(1)*$C$4 | C11: =IF($B11>C$7,(SUMPRODUCT(DCF!$D$16:$H$16/(1+$B11)^DCF!$D$18:$H$18)+DCF!$H$16*(1+C$7)/($B11-C$7)/(1+$B11)^DCF!$H$5-DCF!$C$29)/DCF!$C$31,"n/a") | D11: =IF($B11>D$7,(SUMPRODUCT(DCF!$D$16:$H$16/(1+$B11)^DCF!$D$18:$H$18)+DCF!$H$16*(1+D$7)/($B11-D$7)/(1+$B11)^DCF!$H$5-DCF!$C$29)/DCF!$C$31,"n/a") | E11: =IF($B11>E$7,(SUMPRODUCT(DCF!$D$16:$H$16/(1+$B11)^DCF!$D$18:$H$18)+DCF!$H$16*(1+E$7)/($B11-E$7)/(1+$B11)^DCF!$H$5-DCF!$C$29)/DCF!$C$31,"n/a") | F11: =IF($B11>F$7,(SUMPRODUCT(DCF!$D$16:$H$16/(1+$B11)^DCF!$D$18:$H$18)+DCF!$H$16*(1+F$7)/($B11-F$7)/(1+$B11)^DCF!$H$5-DCF!$C$29)/DCF!$C$31,"n/a") | G11: =IF($B11>G$7,(SUMPRODUCT(DCF!$D$16:$H$16/(1+$B11)^DCF!$D$18:$H$18)+DCF!$H$16*(1+G$7)/($B11-G$7)/(1+$B11)^DCF!$H$5-DCF!$C$29)/DCF!$C$31,"n/a")
B12: =DCF!$C$23+(2)*$C$4 | C12: =IF($B12>C$7,(SUMPRODUCT(DCF!$D$16:$H$16/(1+$B12)^DCF!$D$18:$H$18)+DCF!$H$16*(1+C$7)/($B12-C$7)/(1+$B12)^DCF!$H$5-DCF!$C$29)/DCF!$C$31,"n/a") | D12: =IF($B12>D$7,(SUMPRODUCT(DCF!$D$16:$H$16/(1+$B12)^DCF!$D$18:$H$18)+DCF!$H$16*(1+D$7)/($B12-D$7)/(1+$B12)^DCF!$H$5-DCF!$C$29)/DCF!$C$31,"n/a") | E12: =IF($B12>E$7,(SUMPRODUCT(DCF!$D$16:$H$16/(1+$B12)^DCF!$D$18:$H$18)+DCF!$H$16*(1+E$7)/($B12-E$7)/(1+$B12)^DCF!$H$5-DCF!$C$29)/DCF!$C$31,"n/a") | F12: =IF($B12>F$7,(SUMPRODUCT(DCF!$D$16:$H$16/(1+$B12)^DCF!$D$18:$H$18)+DCF!$H$16*(1+F$7)/($B12-F$7)/(1+$B12)^DCF!$H$5-DCF!$C$29)/DCF!$C$31,"n/a") | G12: =IF($B12>G$7,(SUMPRODUCT(DCF!$D$16:$H$16/(1+$B12)^DCF!$D$18:$H$18)+DCF!$H$16*(1+G$7)/($B12-G$7)/(1+$B12)^DCF!$H$5-DCF!$C$29)/DCF!$C$31,"n/a")
B15: Exit multiple method: WACC (rows) × EV/EBITDA exit multiple (columns)
B16: WACC \ multiple | C16: =DCF!$C$37+(-2)*$G$4 | D16: =DCF!$C$37+(-1)*$G$4 | E16: =DCF!$C$37+(0)*$G$4 | F16: =DCF!$C$37+(1)*$G$4 | G16: =DCF!$C$37+(2)*$G$4
B17: =DCF!$C$23+(-2)*$C$4 | C17: =(SUMPRODUCT(DCF!$D$16:$H$16/(1+$B17)^DCF!$D$18:$H$18)+DCF!$H$17*C$16/(1+$B17)^DCF!$H$5-DCF!$C$29)/DCF!$C$31 | D17: =(SUMPRODUCT(DCF!$D$16:$H$16/(1+$B17)^DCF!$D$18:$H$18)+DCF!$H$17*D$16/(1+$B17)^DCF!$H$5-DCF!$C$29)/DCF!$C$31 | E17: =(SUMPRODUCT(DCF!$D$16:$H$16/(1+$B17)^DCF!$D$18:$H$18)+DCF!$H$17*E$16/(1+$B17)^DCF!$H$5-DCF!$C$29)/DCF!$C$31 | F17: =(SUMPRODUCT(DCF!$D$16:$H$16/(1+$B17)^DCF!$D$18:$H$18)+DCF!$H$17*F$16/(1+$B17)^DCF!$H$5-DCF!$C$29)/DCF!$C$31 | G17: =(SUMPRODUCT(DCF!$D$16:$H$16/(1+$B17)^DCF!$D$18:$H$18)+DCF!$H$17*G$16/(1+$B17)^DCF!$H$5-DCF!$C$29)/DCF!$C$31
B18: =DCF!$C$23+(-1)*$C$4 | C18: =(SUMPRODUCT(DCF!$D$16:$H$16/(1+$B18)^DCF!$D$18:$H$18)+DCF!$H$17*C$16/(1+$B18)^DCF!$H$5-DCF!$C$29)/DCF!$C$31 | D18: =(SUMPRODUCT(DCF!$D$16:$H$16/(1+$B18)^DCF!$D$18:$H$18)+DCF!$H$17*D$16/(1+$B18)^DCF!$H$5-DCF!$C$29)/DCF!$C$31 | E18: =(SUMPRODUCT(DCF!$D$16:$H$16/(1+$B18)^DCF!$D$18:$H$18)+DCF!$H$17*E$16/(1+$B18)^DCF!$H$5-DCF!$C$29)/DCF!$C$31 | F18: =(SUMPRODUCT(DCF!$D$16:$H$16/(1+$B18)^DCF!$D$18:$H$18)+DCF!$H$17*F$16/(1+$B18)^DCF!$H$5-DCF!$C$29)/DCF!$C$31 | G18: =(SUMPRODUCT(DCF!$D$16:$H$16/(1+$B18)^DCF!$D$18:$H$18)+DCF!$H$17*G$16/(1+$B18)^DCF!$H$5-DCF!$C$29)/DCF!$C$31
B19: =DCF!$C$23+(0)*$C$4 | C19: =(SUMPRODUCT(DCF!$D$16:$H$16/(1+$B19)^DCF!$D$18:$H$18)+DCF!$H$17*C$16/(1+$B19)^DCF!$H$5-DCF!$C$29)/DCF!$C$31 | D19: =(SUMPRODUCT(DCF!$D$16:$H$16/(1+$B19)^DCF!$D$18:$H$18)+DCF!$H$17*D$16/(1+$B19)^DCF!$H$5-DCF!$C$29)/DCF!$C$31 | E19: =(SUMPRODUCT(DCF!$D$16:$H$16/(1+$B19)^DCF!$D$18:$H$18)+DCF!$H$17*E$16/(1+$B19)^DCF!$H$5-DCF!$C$29)/DCF!$C$31 | F19: =(SUMPRODUCT(DCF!$D$16:$H$16/(1+$B19)^DCF!$D$18:$H$18)+DCF!$H$17*F$16/(1+$B19)^DCF!$H$5-DCF!$C$29)/DCF!$C$31 | G19: =(SUMPRODUCT(DCF!$D$16:$H$16/(1+$B19)^DCF!$D$18:$H$18)+DCF!$H$17*G$16/(1+$B19)^DCF!$H$5-DCF!$C$29)/DCF!$C$31
B20: =DCF!$C$23+(1)*$C$4 | C20: =(SUMPRODUCT(DCF!$D$16:$H$16/(1+$B20)^DCF!$D$18:$H$18)+DCF!$H$17*C$16/(1+$B20)^DCF!$H$5-DCF!$C$29)/DCF!$C$31 | D20: =(SUMPRODUCT(DCF!$D$16:$H$16/(1+$B20)^DCF!$D$18:$H$18)+DCF!$H$17*D$16/(1+$B20)^DCF!$H$5-DCF!$C$29)/DCF!$C$31 | E20: =(SUMPRODUCT(DCF!$D$16:$H$16/(1+$B20)^DCF!$D$18:$H$18)+DCF!$H$17*E$16/(1+$B20)^DCF!$H$5-DCF!$C$29)/DCF!$C$31 | F20: =(SUMPRODUCT(DCF!$D$16:$H$16/(1+$B20)^DCF!$D$18:$H$18)+DCF!$H$17*F$16/(1+$B20)^DCF!$H$5-DCF!$C$29)/DCF!$C$31 | G20: =(SUMPRODUCT(DCF!$D$16:$H$16/(1+$B20)^DCF!$D$18:$H$18)+DCF!$H$17*G$16/(1+$B20)^DCF!$H$5-DCF!$C$29)/DCF!$C$31
B21: =DCF!$C$23+(2)*$C$4 | C21: =(SUMPRODUCT(DCF!$D$16:$H$16/(1+$B21)^DCF!$D$18:$H$18)+DCF!$H$17*C$16/(1+$B21)^DCF!$H$5-DCF!$C$29)/DCF!$C$31 | D21: =(SUMPRODUCT(DCF!$D$16:$H$16/(1+$B21)^DCF!$D$18:$H$18)+DCF!$H$17*D$16/(1+$B21)^DCF!$H$5-DCF!$C$29)/DCF!$C$31 | E21: =(SUMPRODUCT(DCF!$D$16:$H$16/(1+$B21)^DCF!$D$18:$H$18)+DCF!$H$17*E$16/(1+$B21)^DCF!$H$5-DCF!$C$29)/DCF!$C$31 | F21: =(SUMPRODUCT(DCF!$D$16:$H$16/(1+$B21)^DCF!$D$18:$H$18)+DCF!$H$17*F$16/(1+$B21)^DCF!$H$5-DCF!$C$29)/DCF!$C$31 | G21: =(SUMPRODUCT(DCF!$D$16:$H$16/(1+$B21)^DCF!$D$18:$H$18)+DCF!$H$17*G$16/(1+$B21)^DCF!$H$5-DCF!$C$29)/DCF!$C$31
B23: Current share price | C23: =Assumptions!$C$17

Sheet Comps
B1: Trading comparables (latest fiscal year; $m except per share)
B2: Multiples on the latest reported fiscal year. Negative or extreme multiples are blanked (not meaningful).
B4: Ticker | C4: Company | D4: FY | E4: Price ($) | F4: Shares (m) | G4: Market cap | H4: Debt | I4: Cash + ST inv. | J4: Enterprise value | K4: Revenue | L4: EBITDA | M4: Net income | N4: EV / Revenue | O4: EV / EBITDA | P4: P / E | Q4: EBIT margin
B5: LULU | C5: lululemon athletica inc. | D5: 2025 | E5: 94.285004 | F5: 105.59406 | G5: =E5*F5 | H5: 0 | I5: 1389.737 | J5: =G5+H5-I5 | K5: 11102.6 | L5: 2706.843 | M5: 1579.183 | N5: =IFERROR(J5/K5,"") | O5: =IF(AND(L5>0,J5/L5<=60,J5>0),J5/L5,"") | P5: =IF(AND(M5>0,G5/M5<=100),G5/M5,"") | Q5: 0.19910787
B6: DECK | C6: DECKERS OUTDOOR CORP | D6: 2026 | E6: 83.537498 | F6: 136.41423 | G6: =E6*F6 | H6: 0 | I6: 1602.589 | J6: =G6+H6-I6 | K6: 5472.296 | L6: 1338.676 | M6: 1024.071 | N6: =IFERROR(J6/K6,"") | O6: =IF(AND(L6>0,J6/L6<=60,J6>0),J6/L6,"") | P6: =IF(AND(M6>0,G6/M6<=100),G6/M6,"") | Q6: 0.23078119
B7: CROX | C7: Crocs, Inc. | D7: 2025 | E7: 117.88 | F7: 47.945075 | G7: =E7*F7 | H7: 1334 | I7: 170.276 | J7: =G7+H7-I7 | K7: 4040.647 | L7: 228.797 | M7: -81.198 | N7: =IFERROR(J7/K7,"") | O7: =IF(AND(L7>0,J7/L7<=60,J7>0),J7/L7,"") | P7: =IF(AND(M7>0,G7/M7<=100),G7/M7,"") | Q7: 0.037002737
B8: UAA | C8: Under Armour, Inc. | D8: 2026 | E8: 4.9400001 | F8: 431.937 | G8: =E8*F8 | H8: 591.158 | I8: 395.981 | J8: =G8+H8-I8 | K8: 4966.37 | L8: -53.489 | M8: -495.643 | N8: =IFERROR(J8/K8,"") | O8: =IF(AND(L8>0,J8/L8<=60,J8>0),J8/L8,"") | P8: =IF(AND(M8>0,G8/M8<=100),G8/M8,"") | Q8: -0.032843304
B9: VFC | C9: V F CORP | D9: 2026 | E9: 15.765 | F9: 391.7697 | G9: =E9*F9 | H9: 3530.009 | I9: 823.943 | J9: =G9+H9-I9 | K9: 9605.207 | L9: 857.098 | M9: 254.92 | N9: =IFERROR(J9/K9,"") | O9: =IF(AND(L9>0,J9/L9<=60,J9>0),J9/L9,"") | P9: =IF(AND(M9>0,G9/M9<=100),G9/M9,"") | Q9: 0.060026713
B10: COLM | C10: COLUMBIA SPORTSWEAR CO | D10: 2025 | E10: 56.349998 | F10: 51.193194 | G10: =E10*F10 | H10: 0 | I10: 624.601 | J10: =G10+H10-I10 | K10: 3397.351 | L10: 263.874 | M10: 177.224 | N10: =IFERROR(J10/K10,"") | O10: =IF(AND(L10>0,J10/L10<=60,J10>0),J10/L10,"") | P10: =IF(AND(M10>0,G10/M10<=100),G10/M10,"") | Q10: 0.060941304
B11: NKE | C11: NIKE, Inc. | D11: 2026 | E11: 35.055 | F11: 1484.2 | G11: =E11*F11 | H11: 7893 | I11: 8368 | J11: =G11+H11-I11 | K11: 46398 | L11: 4544 | M11: 3108 | N11: =IFERROR(J11/K11,"") | O11: =IF(AND(L11>0,J11/L11<=60,J11>0),J11/L11,"") | P11: =IF(AND(M11>0,G11/M11<=100),G11/M11,"") | Q11: 0.081835424
C13: Peer 25th percentile | N13: =IFERROR(QUARTILE(N5:N10,1),"") | O13: =IFERROR(QUARTILE(O5:O10,1),"") | P13: =IFERROR(QUARTILE(P5:P10,1),"") | Q13: =IFERROR(QUARTILE(Q5:Q10,1),"")
C14: Peer median | N14: =IFERROR(MEDIAN(N5:N10),"") | O14: =IFERROR(MEDIAN(O5:O10),"") | P14: =IFERROR(MEDIAN(P5:P10),"") | Q14: =IFERROR(MEDIAN(Q5:Q10),"")
C15: Peer 75th percentile | N15: =IFERROR(QUARTILE(N5:N10,3),"") | O15: =IFERROR(QUARTILE(O5:O10,3),"") | P15: =IFERROR(QUARTILE(P5:P10,3),"") | Q15: =IFERROR(QUARTILE(Q5:Q10,3),"")
B17: Implied value per share for NKE ($)
C18: Method | D18: Low (Q1) | E18: Median | F18: High (Q3)
C19: EV / EBITDA | D19: =IFERROR((O13*L11-(Assumptions!$C$22))/F11,"") | E19: =IFERROR((O14*L11-(Assumptions!$C$22))/F11,"") | F19: =IFERROR((O15*L11-(Assumptions!$C$22))/F11,"")
C20: P / E | D20: =IFERROR(P13*M11/F11,"") | E20: =IFERROR(P14*M11/F11,"") | F20: =IFERROR(P15*M11/F11,"")
C21: EV / Revenue | D21: =IFERROR((N13*K11-(Assumptions!$C$22))/F11,"") | E21: =IFERROR((N14*K11-(Assumptions!$C$22))/F11,"") | F21: =IFERROR((N15*K11-(Assumptions!$C$22))/F11,"")

Sheet Valuation
B1: NIKE, Inc. (NKE): valuation summary
B2: Football field, blended price target and rating, all linked to the model.
B4: Method | C4: Low ($) | D4: High ($) | E4: Midpoint ($) | F4: Basis | H4: Chart helper
B5: 52-week trading range (closing prices) | C5: 33.869999 | D5: 69.68 | E5: =IFERROR((C5+D5)/2,"") | F5: Market data | H5: Low | I5: Range
B6: Trading comps: EV / EBITDA (peer Q1–Q3) | C6: =Comps!$D$19 | D6: =Comps!$F$19 | E6: =IFERROR((C6+D6)/2,"") | F6: Comps sheet | G6: =B5 | H6: =C5 | I6: =D5-C5
B7: Trading comps: P / E (peer Q1–Q3) | C7: =Comps!$D$20 | D7: =Comps!$F$20 | E7: =IFERROR((C7+D7)/2,"") | F7: Comps sheet | G7: =B6 | H7: =C6 | I7: =D6-C6
B8: DCF: perpetuity growth (WACC ±0.5pp, g ±0.25pp) | C8: =MIN(Sensitivity!$D$9:$F$11) | D8: =MAX(Sensitivity!$D$9:$F$11) | E8: =IFERROR((C8+D8)/2,"") | F8: Sensitivity sheet | G8: =B7 | H8: =C7 | I8: =D7-C7
B9: DCF: exit multiple (WACC ±0.5pp, multiple ±1x) | C9: =MIN(Sensitivity!$D$18:$F$20) | D9: =MAX(Sensitivity!$D$18:$F$20) | E9: =IFERROR((C9+D9)/2,"") | F9: Sensitivity sheet | G9: =B8 | H9: =C8 | I9: =D8-C8
B10: Scenarios: bear to bull (DCF snapshot) | C10: 22.45255 | D10: 58.324741 | E10: =IFERROR((C10+D10)/2,"") | F10: Snapshot; switch the scenario on Assumptions to recompute live | G10: =B9 | H10: =C9 | I10: =D9-C9
G11: =B10 | H11: =C10 | I11: =D10-C10
B12: Blended price target
B13: Component | C13: Value ($) | D13: Weight | E13: Contribution
B14: DCF: perpetuity growth | C14: =DCF!$C$32 | D14: =Assumptions!$C$42 | E14: =IFERROR(C14*D14,0)
B15: DCF: exit multiple | C15: =DCF!$C$42 | D15: =Assumptions!$C$43 | E15: =IFERROR(C15*D15,0)
B16: Trading comps: EV / EBITDA median | C16: =Comps!$E$19 | D16: =Assumptions!$C$44 | E16: =IFERROR(C16*D16,0)
B17: Price target | C17: =SUM(E14:E16)/SUMPRODUCT(--ISNUMBER(C14:C16),D14:D16)
B18: Current share price | C18: =Assumptions!$C$17
B19: Implied upside / (downside) | C19: =C17/C18-1
B20: Rating | C20: =IF(C19>Assumptions!$C$45,"BUY",IF(C19<Assumptions!$C$46,"SELL","HOLD"))
B22: Scenario snapshot (DCF perpetuity method)
B23: Scenario | C23: Value per share ($) | D23: vs price
B24: Bear | C24: 22.45255 | D24: =C24/$C$18-1
B25: Base | C25: 35.473295 | D25: =C25/$C$18-1
B26: Bull | C26: 58.324741 | D26: =C26/$C$18-1

Sheet Benchmark
B1: NKE vs peers: benchmarking
B2: Peers: LULU, DECK, CROX, UAA, VFC, COLM. Latest fiscal year for each company.
B4: Metric | C4: NKE | D4: Peer median | E4: Peer Q1 | F4: Peer Q3 | G4: Percentile (100 = best) | H4: Verdict
B5: Revenue growth | C5: 0.0019218726 | D5: 0.0095578992 | E5: -0.0091019911 | F5: 0.039086137 | G5: 35.714286 | H5: Worse
B6: Revenue CAGR (3y) | C6: -0.032401823 | D6: 0.018569576 | E6: -0.036690961 | F6: 0.093662394 | G6: 35.714286 | H6: Worse
B7: Gross margin | C7: 0.42913488 | D7: 0.55690181 | E7: 0.5159335 | F7: 0.57428031 | G7: 7.1428571 | H7: Worse
B8: EBIT margin | C8: 0.081835424 | D8: 0.060484008 | E8: 0.042758731 | F8: 0.16456623 | G8: 64.285714 | H8: Better
B9: ROIC | C9: 0.23449449 | D9: 0.12979703 | E9: 0.042988202 | F9: 0.46807974 | G9: 64.285714 | H9: Better
B10: FCF margin | C10: 0.047070994 | D10: 0.07340511 | E10: 0.059407196 | F10: 0.14311023 | G10: 21.428571 | H10: Worse
B11: FCF conversion (FCF / net income) | C11: 0.7027027 | D11: 1.1472471 | E11: 0.94956434 | F11: 1.4630415 | G11: 30 | H11: Worse
B12: Net debt / EBITDA | C12: -0.23877641 | D12: -0.66764197 | E12: -1.4247279 | F12: 3.1572422 | G12: 41.666667 | H12: Worse
B13: Interest coverage (EBIT / interest) | C13: 11.755418 | D13: 3.4572498 | E13: 1.6935109 | F13: 499.17115 | G13: 58.333333 | H13: Better
B14: Inventory days | C14: 103.36637 | D14: 119.2755 | E14: 88.756386 | F14: 127.45373 | G14: 64.285714 | H14: Better
B15: Cash conversion cycle | C15: 100.41463 | D15: 109.30686 | E15: 100.05495 | F15: 109.99508 | G15: 58.333333 | H15: Better
B18: Trend: Revenue growth
B19: Fiscal year | C19: FY2019 | D19: FY2020 | E19: FY2021 | F19: FY2022 | G19: FY2023 | H19: FY2024 | I19: FY2025 | J19: FY2026
B20: NKE | D20: -0.043817266 | E20: 0.1907601 | F20: 0.048767345 | G20: 0.096488975 | H20: 0.0028310912 | I20: -0.098380125 | J20: 0.0019218726
B21: Peer median | C21: 0.10827203 | D21: 0.038574475 | E21: 0.2598657 | F21: 0.28174671 | G21: 0.076702256 | H21: 0.00062809497 | I21: -0.0032211978 | J21: 0.01057541
B22: Peer Q1 | C22: 0.067832846 | D22: -0.10744339 | E22: 0.20766828 | F22: 0.23754253 | G22: 0.014694506 | H22: -0.034077506 | I22: -0.034831846 | J22: -0.01387652
B23: Peer Q3 | C23: 0.15066769 | D23: 0.093536133 | E23: 0.38350044 | F23: 0.29631045 | G23: 0.14219383 | H23: 0.084357626 | I23: 0.038577382 | J23: 0.054096557
B25: Trend: Gross margin
B26: Fiscal year | C26: FY2018 | D26: FY2019 | E26: FY2020 | F26: FY2021 | G26: FY2022 | H26: FY2023 | I26: FY2024 | J26: FY2025 | K26: FY2026
B27: NKE | D27: 0.44671115 | E27: 0.43421651 | F27: 0.44820154 | G27: 0.45983729 | H27: 0.43524611 | I27: 0.44560181 | J27: 0.42734674 | K27: 0.42913488
B28: Peer median | C28: 0.50473188 | D28: 0.50814683 | E28: 0.52930509 | F28: 0.53334674 | G28: 0.52328828 | H28: 0.51296758 | I28: 0.53596268 | J28: 0.5504425 | K28: 0.54779819
B29: Peer Q1 | C29: 0.4837053 | D29: 0.49898464 | E29: 0.49631437 | F29: 0.51854365 | G29: 0.51027874 | H29: 0.49786832 | I29: 0.50540702 | J29: 0.51270384 | K29: 0.50131449
B30: Peer Q3 | C30: 0.52414911 | D30: 0.53856958 | E30: 0.54987409 | F30: 0.56751521 | G30: 0.54513885 | H30: 0.54899012 | I30: 0.57976126 | J30: 0.57559997 | K30: 0.56241839
B32: Trend: EBIT margin
B33: Fiscal year | C33: FY2018 | D33: FY2019 | E33: FY2020 | F33: FY2021 | G33: FY2022 | H33: FY2023 | I33: FY2024 | J33: FY2025 | K33: FY2026
B34: NKE | D34: 0.121993 | E34: 0.08328209 | F34: 0.15575464 | G34: 0.14290302 | H34: 0.115489 | I34: 0.12287294 | J34: 0.079941264 | K34: 0.081835424
B35: Peer median | C35: 0.091544356 | D35: 0.12287159 | E35: 0.12147744 | F35: 0.17108133 | G35: 0.16378831 | H35: 0.1350092 | I35: 0.14834446 | J35: 0.048972021 | K35: 0.060026713
B36: Peer Q1 | C36: 0.042177213 | D36: 0.10738779 | E36: 0.063203857 | F36: 0.098748352 | G36: 0.13783365 | H36: 0.089249086 | I36: 0.050313531 | J36: 0.033220927 | K36: 0.013591704
B37: Peer Q3 | C37: 0.14759738 | D37: 0.15395813 | E37: 0.15753552 | F37: 0.20934989 | G37: 0.17925277 | H37: 0.21127034 | I37: 0.23156783 | J37: 0.16456623 | K37: 0.14540395
B39: Trend: ROIC
B40: Fiscal year | C40: FY2018 | D40: FY2019 | E40: FY2020 | F40: FY2021 | G40: FY2022 | H40: FY2023 | I40: FY2024 | J40: FY2025 | K40: FY2026
B41: NKE | D41: 0.50975855 | E41: 0.32650221 | F41: 0.67656962 | G41: 0.59430136 | H41: 0.40341704 | I41: 0.44706771 | J41: 0.25792486 | K41: 0.23449449
B42: Peer median | C42: 0.30523912 | D42: 0.38304717 | E42: 0.30933906 | F42: 0.53453194 | G42: 0.35659152 | H42: 0.2451434 | I42: 0.26342451 | J42: 0.098486139 | K42: 0.089954532
B43: Peer Q1 | C43: 0.20691705 | D43: 0.18855434 | E43: 0.10450386 | F43: 0.34665837 | G43: 0.2370164 | H43: 0.17660695 | I43: 0.12564124 | J43: 0.025860474 | K43: 0.014867879
B44: Peer Q3 | C44: 0.46007415 | D44: 0.62940907 | E44: 0.51242785 | F44: 0.77394638 | G44: 0.49056035 | H44: 0.52839933 | I44: 0.69607117 | J44: 0.46807974 | K44: 0.79391933
B46: Trend: FCF margin
B47: Fiscal year | C47: FY2018 | D47: FY2019 | E47: FY2020 | F47: FY2021 | G47: FY2022 | H47: FY2023 | I47: FY2024 | J47: FY2025 | K47: FY2026
...

Sheet Sources
B1: Data provenance
B2: Every historical value: the XBRL tag it came from and the SEC filing (click to open).
B4: Line item | C4: FY | D4: Period end | E4: Value ($m) | F4: XBRL tag | G4: Form | H4: Accession | I4: Filed
B5: Share repurchases | C5: 2019 | D5: 2019-05-31 | E5: 4286 | F5: PaymentsForRepurchaseOfCommonStock | G5: 10-K | H5: 0000320187-21-000028 | I5: 2021-07-20
B6: Share repurchases | C6: 2020 | D6: 2020-05-31 | E6: 3067 | F6: PaymentsForRepurchaseOfCommonStock | G6: 10-K | H6: 0000320187-22-000038 | I6: 2022-07-21
B7: Share repurchases | C7: 2021 | D7: 2021-05-31 | E7: 608 | F7: PaymentsForRepurchaseOfCommonStock | G7: 10-K | H7: 0000320187-23-000039 | I7: 2023-07-20
B8: Share repurchases | C8: 2022 | D8: 2022-05-31 | E8: 4014 | F8: PaymentsForRepurchaseOfCommonStock | G8: 10-K | H8: 0000320187-24-000044 | I8: 2024-07-25
B9: Share repurchases | C9: 2023 | D9: 2023-05-31 | E9: 5480 | F9: PaymentsForRepurchaseOfCommonStock | G9: 10-K | H9: 0000320187-25-000047 | I9: 2025-07-17
B10: Share repurchases | C10: 2024 | D10: 2024-05-31 | E10: 4250 | F10: PaymentsForRepurchaseOfCommonStock | G10: 10-K | H10: 0000320187-26-000088 | I10: 2026-07-15
B11: Share repurchases | C11: 2025 | D11: 2025-05-31 | E11: 2985 | F11: PaymentsForRepurchaseOfCommonStock | G11: 10-K | H11: 0000320187-26-000088 | I11: 2026-07-15
B12: Share repurchases | C12: 2026 | D12: 2026-05-31 | E12: 146 | F12: PaymentsForRepurchaseOfCommonStock | G12: 10-K | H12: 0000320187-26-000088 | I12: 2026-07-15
B13: Capital expenditure | C13: 2019 | D13: 2019-05-31 | E13: 1119 | F13: PaymentsToAcquirePropertyPlantAndEquipment | G13: 10-K | H13: 0000320187-21-000028 | I13: 2021-07-20
B14: Capital expenditure | C14: 2020 | D14: 2020-05-31 | E14: 1086 | F14: PaymentsToAcquirePropertyPlantAndEquipment | G14: 10-K | H14: 0000320187-22-000038 | I14: 2022-07-21
B15: Capital expenditure | C15: 2021 | D15: 2021-05-31 | E15: 695 | F15: PaymentsToAcquirePropertyPlantAndEquipment | G15: 10-K | H15: 0000320187-23-000039 | I15: 2023-07-20
B16: Capital expenditure | C16: 2022 | D16: 2022-05-31 | E16: 758 | F16: PaymentsToAcquirePropertyPlantAndEquipment | G16: 10-K | H16: 0000320187-24-000044 | I16: 2024-07-25
... B174: Net income | C174: 2026 | D174: 2026-05-31 | E174: 3108 | F174: NetIncomeLoss | G174: 10-K | H174: 0000320187-26-000088 | I174: 2026-07-15
B175: Operating income (EBIT) | C175: 2019 | D175: derived | E175: 4772 | F175: DERIVED: gross profit − SG&A − R&D
B176: Operating income (EBIT) | C176: 2020 | D176: derived | E176: 3115 | F176: DERIVED: gross profit − SG&A − R&D
B177: Operating income (EBIT) | C177: 2021 | D177: derived | E177: 6937 | F177: DERIVED: gross profit − SG&A − R&D
B178: Operating income (EBIT) | C178: 2022 | D178: derived | E178: 6675 | F178: DERIVED: gross profit − SG&A − R&D
B179: Operating income (EBIT) | C179: 2023 | D179: derived | E179: 5915 | F179: DERIVED: gross profit − SG&A − R&D
B180: Operating income (EBIT) | C180: 2024 | D180: derived | E180: 6311 | F180: DERIVED: gross profit − SG&A − R&D
B181: Operating income (EBIT) | C181: 2025 | D181: derived | E181: 3702 | F181: DERIVED: gross profit − SG&A − R&D
B182: Operating income (EBIT) | C182: 2026 | D182: derived | E182: 3797 | F182: DERIVED: gross profit − SG&A − R&D
B183: Accounts payable | C183: 2019 | D183: 2019-05-31 | E183: 2612 | F183: AccountsPayableCurrent | G183: 10-K | H183: 0000320187-20-000047 | I183: 2020-07-24
B184: Accounts payable | C184: 2020 | D184: 2020-05-31 | E184: 2248 | F184: AccountsPayableCurrent | G184: 10-K | H184: 0000320187-21-000028 | I184: 2021-07-20
B185: Accounts payable | C185: 2021 | D185: 2021-05-31 | E185: 2836 | F185: AccountsPayableCurrent | G185: 10-K | H185: 0000320187-22-000038 | I185: 2022-07-21
B186: Accounts payable | C186: 2022 | D186: 2022-05-31 | E186: 3358 | F186: AccountsPayableCurrent | G186: 10-K | H186: 0000320187-23-000039 | I186: 2023-07-20
B187: Accounts payable | C187: 2023 | D187: 2023-05-31 | E187: 2862 | F187: AccountsPayableCurrent | G187: 10-K | H187: 0000320187-24-000044 | I187: 2024-07-25
B188: Accounts payable | C188: 2024 | D188: 2024-05-31 | E188: 2851 | F188: AccountsPayableCurrent | G188: 10-K | H188: 0000320187-25-000047 | I188: 2025-07-17
B189: Accounts payable | C189: 2025 | D189: 2025-05-31 | E189: 3479 | F189: AccountsPayableCurrent | G189: 10-K | H189: 0000320187-26-000088 | I189: 2026-07-15
B190: Accounts payable | C190: 2026 | D190: 2026-05-31 | E190: 3600 | F190: AccountsPayableCurrent | G190: 10-K | H190: 0000320187-26-000088 | I190: 2026-07-15
B191: PP&E, net | C191: 2019 | D191: 2019-05-31 | E191: 4744 | F191: PropertyPlantAndEquipmentNet | G191: 10-K | H191: 0000320187-20-000047 | I191: 2020-07-24
B192: PP&E, net | C192: 2020 | D192: 2020-05-31 | E192: 4866 | F192: PropertyPlantAndEquipmentNet | G192: 10-K | H192: 0000320187-21-000028 | I192: 2021-07-20
B193: PP&E, net | C193: 2021 | D193: 2021-05-31 | E193: 4904 | F193: PropertyPlantAndEquipmentNet | G193: 10-K | H193: 0000320187-22-000038 | I193: 2022-07-21
B194: PP&E, net | C194: 2022 | D194: 2022-05-31 | E194: 4791 | F194: PropertyPlantAndEquipmentNet | G194: 10-K | H194: 0000320187-23-000039 | I194: 2023-07-20
... B261: Total assets | C261: 2026 | D261: 2026-05-31 | E261: 38410 | F261: Assets | G261: 10-K | H261: 0000320187-26-000088 | I261: 2026-07-15
